Workbook

Sheet Übersicht
A1: IKS-Kontrollmatrix für Umwelt-, Sozial- und Produktaussagen (Claims)
A2: EmpCo (Richtlinie (EU) 2024/825) · UWG n. F. · Art. 246, 246a EGBGB · Stand 30.09.2026 · Entwurf v1.0 · intern, keine Rechtsberatung
A4: Zweck
A5: Die Matrix übersetzt die EmpCo-Anforderungen in Kontrollen des internen Kontrollsystems: je Risiko eine Kontrolle mit Kontrollziel, Art, Frequenz, Verantwortung, Nachweis und Prüfungshandlung. Die Kontrollen K1–K12 entsprechen Kapitel 7.3 des Arbeitsdokuments „EmpCo in bestehenden GRC-Strukturen“ (29.09.2026); K13–K23 ergänzen Rahmen, Inventur, IT, Lieferanten, Dritte, Vertrieb, KI, Vergleiche, Produktentwicklung, Altbestände und Überwachung. EmpCo schreibt keine Kontrollen vor; die Kontrollen dienen dazu, die gesetzlichen Pflichten verlässlich zu erfüllen und nachzuweisen.
A7: Aufbau
A8: Kontrollmatrix | B8: 23 Kontrollen in Prozessreihenfolge; Spalten U bis AA zum Ausfüllen (Status und Tests)
A9: Kontrollziele | B9: Kontrollziele KZ1–KZ9 mit zugeordneten Kontrollen
A10: Anforderungen | B10: EmpCo-Anforderungen A1–A14 mit Fundstellen und zugeordneten Kontrollen
A11: Quellen | B11: Fundstellen mit Links und Validierungsstatus
A13: So wird die Matrix genutzt
A14: • Gelb hinterlegte Spalten der Kontrollmatrix (U bis AA) ausfüllen. Die Spalten A bis T sind Vorschläge und können an das Unternehmen angepasst werden.
A15: • Auswahllisten: Umsetzungsstatus (offen, in Umsetzung, umgesetzt, nicht relevant), Ergebnis Design (angemessen, nicht angemessen, offen), Ergebnis Wirksamkeit (wirksam, nicht wirksam, nicht getestet).
A16: • Datumsfelder im Format TT.MM.JJJJ eingeben. Die Kennzahlen unten aktualisieren sich automatisch.
A17: • Kennzeichnung „Verbindlichkeit“: Pflicht = unmittelbar gesetzlich gefordert; Organisation = nicht vorgeschrieben, aber nötig, um die Pflichten verlässlich zu erfüllen; Best Practice = darüber hinaus.
A18: • Kleine Unternehmen beginnen mit den Kontrollen, deren Spalte „KMU-Minimum“ „ja“ enthält (Filter in Zeile 3).
A20: Beispiel für eine ausgefüllte Zeile (Format)
A21: ID | B21: Umsetzungsstatus | C21: Verantwortliche Person | D21: Design beurteilt am | E21: Ergebnis Design | F21: Wirksamkeit getestet am | G21: Ergebnis Wirksamkeit
A22: K1 | B22: umgesetzt | C22: Leitung E-Commerce | D22: 15.10.2026 | E22: angemessen | F22: 15.01.2027 | G22: wirksam
A23: Feststellungen / Maßnahmen, Beispiel: „Stichprobe von 10 Produktseiten ohne Abweichung; Pflichtfeld im Web-CMS seit 01.10.2026 aktiv.“
A25: Kennzahlen (werden aus der Kontrollmatrix berechnet)
A26: Kontrollen | B26: Anzahl
A27: Kontrollen gesamt | B27: =COUNTA(Kontrollmatrix!$A$4:$A$26) -> 23
A28: davon Schlüsselkontrollen | B28: =COUNTIF(Kontrollmatrix!$Q$4:$Q$26,"ja") -> 14
A29: davon Teil der KMU-Mindestausstattung (KMU-Minimum „ja …“) | B29: =COUNTIF(Kontrollmatrix!$S$4:$S$26,"ja*") -> 16
A30: davon nur bei Nutzung oder Relevanz | B30: =COUNTIF(Kontrollmatrix!$S$4:$S$26,"bei*") -> 5
A31: mit präventivem Anteil | B31: =COUNTIF(Kontrollmatrix!$H$4:$H$26,"*präventiv*") -> 17
A32: mit detektivem Anteil | B32: =COUNTIF(Kontrollmatrix!$H$4:$H$26,"*detektiv*") -> 10
A33: korrektiv | B33: =COUNTIF(Kontrollmatrix!$H$4:$H$26,"*korrektiv*") -> 2
A34: mit Pflichtbezug (Verbindlichkeit enthält „Pflicht“) | B34: =COUNTIF(Kontrollmatrix!$P$4:$P$26,"*Pflicht*") -> 8
A35: ganz oder teilweise Best Practice | B35: =COUNTIF(Kontrollmatrix!$P$4:$P$26,"*Best Practice*") -> 4
A37: Umsetzungsstatus | B37: Anzahl
A38: offen | B38: =COUNTIF(Kontrollmatrix!$U$4:$U$26,"offen") -> 0
A39: in Umsetzung | B39: =COUNTIF(Kontrollmatrix!$U$4:$U$26,"in Umsetzung") -> 0
A40: umgesetzt | B40: =COUNTIF(Kontrollmatrix!$U$4:$U$26,"umgesetzt") -> 0
A41: nicht relevant | B41: =COUNTIF(Kontrollmatrix!$U$4:$U$26,"nicht relevant") -> 0
A42: ohne Angabe | B42: =$B$27-COUNTA(Kontrollmatrix!$U$4:$U$26) -> 23
A43: Umsetzungsquote (umgesetzt / relevante Kontrollen) | B43: =IFERROR($B$40/($B$27-$B$41),0) -> 0
A45: Tests | B45: Anzahl
A46: Design: angemessen | B46: =COUNTIF(Kontrollmatrix!$X$4:$X$26,"angemessen") -> 0
A47: Design: nicht angemessen | B47: =COUNTIF(Kontrollmatrix!$X$4:$X$26,"nicht angemessen") -> 0
...

Sheet Kontrollmatrix
A1: IKS-Kontrollmatrix für Umwelt-, Sozial- und Produktaussagen (Claims) nach EmpCo/UWG · Stand 30.09.2026 · Entwurf v1.0
A2: RISIKO UND KONTROLLZIEL | G2: KONTROLLE | N2: EINORDNUNG UND UMSETZUNG | U2: STATUS UND TEST – BITTE AUSFÜLLEN
A3: ID | B3: Teilprozess | C3: Risiko (Was kann schiefgehen?) | D3: EmpCo-Anforderung (Nr., Norm) | E3: Kontrollziel | F3: COSO-Komponente | G3: Kontrollaktivität | H3: Kontrollart | I3: Durchführung | J3: Frequenz | K3: Kontroll- verantwortung | L3: Nachweis / Dokumentation | M3: Prüfungshandlung (Wirksamkeitstest) | N3: Neu oder Anpassung | O3: Umsetzungsbeispiel | P3: Verbindlichkeit | Q3: Schlüssel- kontrolle | R3: KMU- Relevanz | S3: KMU- Minimum | T3: Bezug (Dokument, RB) | U3: Umsetzungs- status | V3: Verantwortliche Person | W3: Design beurteilt am | X3: Ergebnis Design | Y3: Wirksamkeit getestet am | Z3: Ergebnis Wirksamkeit | AA3: Feststellungen / Maßnahmen
A4: K23 | B4: 0 Rahmen (unternehmensweit) | C4: Es gibt keine verbindlichen Regeln und Zuständigkeiten für Claims; Kontrollen werden uneinheitlich oder gar nicht durchgeführt. | D4: A1–A14; allgemeine Organisationspflicht der Geschäftsleitung (§ 93 AktG, § 43 GmbHG) | E4: alle (Grundlage) | F4: Kontrollumfeld | G4: Die Geschäftsleitung beschließt eine Claims-Richtlinie (Geltungsbereich, Negativliste, Evidenzstandards, Risikoklassen, Freigabematrix, Dokumentation) und benennt einen Claim-Governance-Owner. Die Richtlinie wird jährlich und bei Rechtsänderungen aktualisiert; die Zielgruppen bestätigen die Kenntnisnahme. | H4: präventiv | I4: manuell | J4: jährlich und anlassbezogen | K4: Geschäftsleitung; Claim-Governance-Owner | L4: Beschluss der Geschäftsleitung; Richtlinie mit Versionsstand; Kenntnisnahmen | M4: Einsicht in Beschluss und aktuelle Fassung; Stichprobe von 5 Kenntnisnahmen aus Marketing und Vertrieb. | N4: Neu (Policy-Modul), eingebettet in das bestehende Richtlinienwesen | O4: Dreiseitige Claims-Richtlinie, in der GF-Sitzung beschlossen und im Intranet veröffentlicht | P4: Organisation | Q4: ja | R4: hoch | S4: ja | T4: Word Kap. 5.3; RB Kap. 6.10 (Baustein 1)
A5: K13 | B5: 1 Erfassung und Inventar | C5: Claims in einzelnen Kanälen sind nicht bekannt, etwa auf Verpackungen, Marktplätzen, in Social Media, alten PDF-Broschüren oder in Produkt- und Markennamen, und werden deshalb nie geprüft. | D5: A1–A14 (schon eine einzelne Aussage genügt für einen Verstoß) | E5: KZ1 Vollständigkeit | F5: Risikobeurteilung | G5: Einmalige Vollinventur aller Kanäle (Verpackung, Etikett, Website, Shop, Marktplätze, Social Media, Kataloge, Vertriebsunterlagen, Produkt- und Markennamen, Siegel und Icons) mit Entscheidung „behalten, ändern, streichen“. Danach wird jeder neue Claim vor der Nutzung im Claim-Register erfasst. Die Inventur wird jährlich aktualisiert. | H5: detektiv (Inventur); präventiv (Registerpflicht) | I5: manuell | J5: einmalig, danach jährlich; Registerpflicht laufend | K5: Claim-Governance-Owner mit Marketing, Produktmanagement und E-Commerce | L5: Inventurprotokoll; Claim-Register mit Entscheidung je Claim | M5: Stichprobe von 10 Aussagen aus Website, Verpackung und Social Media: Jede Aussage ist im Register erfasst und entschieden. | N5: Neu (ein Claim-Register besteht meist nicht) | O5: Excel-Register mit Claim-ID, Wortlaut, Kanal, Risikoklasse, Evidenzlink, Freigabe und Ablaufdatum | P5: Organisation (dient Pflicht) | Q5: ja | R5: hoch | S5: ja | T5: RB C01; RB Kap. 6.10 (Bausteine 2 und 3)
A6: K2 | B6: 2 Entwurf und Klassifizierung | C6: Eine per se unzulässige Aussage wird verwendet: allgemeine Umweltaussage ohne Spitzenleistung, Teil als Ganzes, kompensationsbasierte Produktneutralität, gesetzliche Pflicht als Besonderheit, Obsoleszenz-Praktiken; dazu irrelevante Vorteile. | D6: A2, A4, A5, A8, A10 – Anhang Nr. 4a, 4b, 4c, 10a, 23d UWG; A7 – § 5 Abs. 3 Nr. 3 UWG | E6: KZ2 Zulässigkeit | F6: Kontrollaktivitäten | G6: Jeder Claim-Entwurf wird vor der fachlichen Prüfung gegen die Negativliste geprüft und einer Risikoklasse zugeordnet (0, A, B, C). Allgemeine Begriffe bleiben nur mit anerkannter hervorragender Umweltleistung (EU-Umweltzeichen, amtlich anerkanntes Typ-I-Zeichen) oder klarer Spezifizierung im selben Medium. Zusätzlich wird geprüft, ob eine beworbene Eigenschaft ohnehin gesetzlich vorgeschrieben ist oder ein irrelevanter Vorteil beworben wird. Klasse 0 wird nicht weiterbearbeitet. | H6: präventiv | I6: manuell (optional IT-gestützte Stichwortsuche) | J6: je Claim | K6: Claim-Governance-Owner (Compliance) | L6: Klassifizierungsvermerk im Register (Klasse, Ergebnis der Negativlisten-Prüfung) | M6: Stichprobe von 10 freigegebenen Claims: Klassifizierungsvermerk vorhanden; erneute Prüfung gegen die Negativliste ergibt keinen Treffer. | N6: Neu (Negativliste); eingebaut in die bestehende Werbefreigabe | O6: „Umweltfreundlich verpackt“ ist ein Treffer und wird ersetzt durch „Verpackung zu 80 % aus recyceltem Kunststoff“ | P6: Organisation (dient Pflicht) | Q6: ja | R6: hoch | S6: ja | T6: Word K2; RB C03, C04, C06; RB Kap. 6.4
A7: K18 | B7: 2 Entwurf und Klassifizierung | C7: KI-Werkzeuge erzeugen unzulässige oder unbelegte Claims in großer Zahl, etwa in Produkttexten oder Chatbot-Antworten. | D7: A1, A2 – § 5 UWG; Anhang Nr. 4a UWG | E7: KZ1 Vollständigkeit; KZ2 Zulässigkeit | F7: Kontrollaktivitäten | G7: Ein Negativlisten-Filter prüft Prompts und Ausgaben. KI-generierte Texte mit Umwelt-, Sozial- oder Haltbarkeitsbezug werden vor der Veröffentlichung von einem Menschen freigegeben. Prompt, Ausgabe und Freigabe werden protokolliert. | H7: präventiv | I7: automatisiert (Filter) und manuell (Freigabe) | J7: je generiertem Text | K7: Digital, E-Commerce mit Compliance | L7: Filterkonfiguration; Freigabeprotokoll; Logs | M7: Filtertest mit 10 Begriffen der Negativliste; Stichprobe von 10 veröffentlichten KI-Texten auf Freigabenachweis. | N7: Neu (nur bei KI-Nutzung) | O7: Ein Sprachmodell schreibt Shop-Texte; „nachhaltig produziert“ wird vom Filter markiert und vor Veröffentlichung gestrichen | P7: Organisation; automatisierter Filter: Best Practice | Q7: nein | R7: bei Nutzung | S7: bei Nutzung (menschliche Freigabe) | T7: RB C18; RB Kap. 13
A8: K3 | B8: 3 Evidenz und fachliche Prüfung | C8: Der Claim ist unrichtig, überdehnt (Teil als Ganzes), methodisch nicht haltbar oder im Streitfall nicht belegbar. | D8: A1, A4, A12 – § 5 Abs. 2 Nr. 1 UWG; Anhang Nr. 4b UWG; Art. 12 UGP-RL | E8: KZ3 Tatsächlichkeit und Richtigkeit; KZ4 Darstellung | F8: Kontrollaktivitäten | G8: Der fachliche Owner prüft vor der Freigabe Daten und Quelle, Berechnung, Methode (mit Begründung der Methodenwahl), Scope-Kongruenz (Geltungsbereich der Aussage = Geltungsbereich der Evidenz) sowie Datenstand und Gültigkeit. Das Ergebnis wird als Prüfvermerk im Evidenzdossier festgehalten; der Prüfer ist nicht der Ersteller. | H8: präventiv | I8: manuell | J8: je Claim | K8: Fachlicher Claim-Owner (Sustainability, Produktmanagement, QM) | L8: Evidenzdossier mit Prüfvermerk (Datum, Name, Ergebnis) | M8: Stichprobe von 10 Claims: Dossier vollständig (Daten, Methode, Scope, Gültigkeit); eine quantitative Aussage wird nachgerechnet. | N8: Neu (Dossierstandard); nutzt die bestehende Dokumentenlenkung | O8: „80 % Rezyklat“: Lieferantenzertifikat, Stückliste, Berechnung des Gewichtsanteils, Prüfvermerk | P8: Organisation (dient Pflicht) | Q8: ja | R8: hoch | S8: ja | T8: Word K3; RB C05, C07, C08; RB Kap. 6.5, 6.7
A9: K15 | B9: 3 Evidenz und fachliche Prüfung | C9: Claims beruhen auf Lieferantenangaben, die fehlen, falsch oder abgelaufen sind oder für ein anderes Material bzw. einen anderen Standort gelten. | D9: A1, A12 – § 5 UWG; Art. 12 UGP-RL | E9: KZ3 Tatsächlichkeit und Richtigkeit; KZ5 Gültigkeit | F9: Kontrollaktivitäten | G9: Claimrelevante Zertifikate und Erklärungen werden bei der Lieferantenfreigabe, jährlich und stichprobenartig beim Wareneingang geprüft: Aussteller, Gültigkeit, Geltungsbereich (Material, Standort, Produkt) und Übereinstimmung mit dem Claim. Lieferverträge enthalten Nachweis- und Änderungsmeldepflichten. | H9: präventiv und detektiv | I9: manuell | J9: bei Lieferantenfreigabe; jährlich; Stichprobe beim Wareneingang | K9: Einkauf mit QM | L9: Lieferantenakte; Zertifikatsliste mit Ablaufdaten | M9: Stichprobe von 5 claimrelevanten Lieferanten: gültiges Zertifikat vorhanden, Geltungsbereich passt zum Claim. | N9: Anpassung (bestehende Lieferantenbewertung und Wareneingangsprüfung erweitern) | O9: Rezyklatzertifikat des Folienlieferanten mit Ablaufdatum, im Claim-Register verknüpft | P9: Organisation | Q9: ja | R9: mittel | S9: ja, wenn Claims auf Lieferantendaten beruhen | T9: RB C13; RB Kap. 8.4; Word Kap. 8 (Supplier Evidence)
A10: K20 | B10: 3 Evidenz und fachliche Prüfung | C10: Ein Vergleich („30 % weniger CO2 als das Vorgängermodell“, „die grünere Wahl“) beruht auf ungleicher Methode oder nennt Methode, verglichene Produkte und Aktualisierung nicht. | D10: A9 – Art. 7 Abs. 7 UGP-RL; § 5b Abs. 3a UWG; § 6 UWG | E10: KZ3 Tatsächlichkeit und Richtigkeit; KZ4 Darstellung | F10: Kontrollaktivitäten | G10: Für jede Vergleichsaussage dokumentiert der Owner Vergleichsbasis, Methode, verglichene Produkte bzw. Anbieter und Aktualisierungsturnus. Legal prüft, ob diese Angaben in der Aussage bzw. im selben Medium bereitgestellt werden. | H10: präventiv | I10: manuell | J10: je Vergleichsaussage | K10: Marketing mit Legal | L10: Methodenblatt im Dossier; Prüfvermerk Legal | M10: Alle Vergleichsaussagen im Register: Methodenblatt vorhanden, Pflichtangaben im Medium sichtbar. | N10: Anpassung (bestehende Rechtsprüfung vergleichender Werbung erweitern) | O10: Produktseite nennt Vergleichsprodukt, Bezugsjahr und Methode (z. B. CO2-Fußabdruck nach ISO 14067) | P10: Organisation (dient Pflicht) | Q10: nein | R10: gering bis mittel | S10: bei Nutzung | T10: RB C08; RB Kap. 3.7, 6.5
A11: K4 | B11: 4 Freigabe | C11: Ein Claim wird vom Ersteller selbst oder ohne die erforderliche Kompetenz freigegeben. | D11: alle; Zurechnung nach § 8 Abs. 2 UWG (A13) | E11: KZ6 Autorisierung | F11: Kontrollaktivitäten | G11: Freigabe nach Freigabematrix: Klasse C durch die Leitung Marketing, Klasse B durch Compliance, Klasse A (u. a. Zukunfts-, Klima-, Vergleichs-, Haltbarkeits- und Siegelaussagen sowie Aussagen über das ganze Unternehmen) durch die Geschäftsleitung nach rechtlicher Prüfung. Klasse 0 wird nicht freigegeben. Ersteller, fachlicher Prüfer und Freigeber sind verschiedene Personen. | H11: präventiv | I11: manuell (workflowgestützt möglich) | J11: je Claim | K11: Compliance; Geschäftsleitung für Klasse A | L11: Freigabelog im Register (Name, Rolle, Datum, Version) | M11: Stichprobe von 10 Claims: Freigabe durch die zuständige Instanz laut Matrix; Ersteller ≠ Freigeber; Freigabe vor Veröffentlichung. | N11: Anpassung (Kompetenzordnung und bestehende Werbefreigabe um Risikoklassen erweitern) | O11: „Klimaneutral bis 2035“ nur mit GF-Beschluss; Newsletter-Claim der Klasse C durch die Leitung Marketing | P11: Organisation | Q11: ja | R11: hoch | S11: ja | T11: Word K4; RB C09, C10; RB Kap. 6.6
A12: K1 | B12: 5 Veröffentlichung | C12: Nicht freigegebene oder nachträglich geänderte Fassungen werden veröffentlicht (Website, Shop, Verpackung, Druck, Social Media). | D12: A1–A14, insbesondere A2–A5 | E12: KZ6 Autorisierung; KZ1 Vollständigkeit | F12: Kontrollaktivitäten | G12: Veröffentlichung und Druckfreigabe nur mit gültiger Claim-ID und freigegebener Version aus dem Register. In Web-CMS, DAM oder PIM als Pflichtfeld bzw. Workflow-Status umgesetzt, sonst als Checkliste in der Druck- und Verpackungsfreigabe. | H12: präventiv | I12: automatisiert (System) oder manuell (Checkliste) | J12: je Veröffentlichung | K12: Marketing, E-Commerce, Verpackungsentwicklung | L12: Systemprotokoll bzw. Druckfreigabe mit Claim-ID; Belegexemplar oder Screenshot | M12: Stichprobe von 10 veröffentlichten Inhalten und Verpackungen: Claim-ID vorhanden, Wortlaut entspricht der freigegebenen Version. | N12: Anpassung (bestehende Druck- und Webfreigabe um das Pflichtfeld Claim-ID erweitern) | O12: Das Web-CMS schaltet eine Produktseite mit Umweltbezug erst nach Eintrag der Claim-ID frei | P12: Organisation | Q12: ja | R12: hoch | S12: ja (als Checkliste) | T12: Word K1; RB C11
A13: K14 | B13: 5 Veröffentlichung | C13: Unberechtigte Personen, etwa Agenturen, ändern oder veröffentlichen Inhalte an der Freigabe vorbei. | D13: alle | E13: KZ6 Autorisierung | F13: Kontrollaktivitäten (IT) | G13: Veröffentlichungsrechte in Web-CMS, Shop, PIM und Social-Media-Konten sind auf definierte Rollen beschränkt; Änderungen werden protokolliert. Die Berechtigungen werden halbjährlich überprüft. | H13: präventiv und detektiv | I13: IT-gestützt | J13: laufend; Überprüfung halbjährlich | K13: IT mit Marketing Operations | L13: Berechtigungsliste; Protokoll der Überprüfung; Änderungslog | M13: Abgleich der Berechtigungsliste mit dem Rollenkonzept; Stichprobe im Änderungslog. | N13: Anpassung (bestehende IT-Berechtigungskontrollen auf Content-Systeme ausweiten) | O13: Agentur-Zugänge zum Shop mit Entwurfs-, aber ohne Veröffentlichungsrecht | P13: Organisation | Q13: nein | R13: mittel | S13: optional | T13: Word Kap. 7.4 (IT-Kontrollen)
A14: K10 | B14: 6 Pflichtinformationen | C14: Vorvertragliche Pflichtinformationen fehlen oder sind falsch: harmonisierter Gewährleistungshinweis, Label zur Haltbarkeitsgarantie, Mindestdauer von Software-Updates, Reparatur- und Ersatzteilinformationen, umweltfreundliche Lieferoptionen. | D14: A11 – Art. 246, 246a EGBGB; VRRL Art. 5, 6; DVO (EU) 2025/1960 | E14: KZ9 Pflichtinformationen | F14: Kontrollaktivitäten | G14: Das Datenmodell in PIM und Shop enthält Pflichtattribute; Artikel ohne vollständige Pflichtangaben werden nicht freigeschaltet. Herstellerangaben (Haltbarkeitsgarantie, Update-Dauer, Ersatzteile) werden bei der Listung angefordert und bei Änderungen aktualisiert. Ein Teil der Pflichten greift nur, soweit der Hersteller die Informationen bereitstellt. | H14: präventiv | I14: automatisiert (Pflichtfeldlogik) | J14: laufend; Datenqualitätsbericht monatlich | K14: E-Commerce, Produktdatenmanagement | L14: Validierungsregeln im PIM; Datenqualitätsbericht | M14: Stichprobe von 10 Artikelseiten: Gewährleistungshinweis sichtbar; Label bei Herstellergarantie; Pflichtangaben vollständig. | N14: Anpassung (bestehendes PIM-Datenmodell erweitern) | O14: Pflichtattribut „Haltbarkeitsgarantie Hersteller (Jahre)“ steuert automatisch die Anzeige des Labels | P14: Organisation (dient Pflicht) | Q14: ja | R14: hoch im Onlinehandel | S14: ja, bei Onlinehandel | T14: Word K10
A15: K16 | B15: 7 Dritte und Vertrieb | C15: Agenturen, Influencer und Händler verwenden eigene, nicht freigegebene Claims; Unterlassungs- und Beseitigungsansprüche richten sich auch gegen das Unternehmen. | D15: A13 – § 8 Abs. 2 UWG | E15: KZ6 Autorisierung; KZ1 Vollständigkeit | F15: Kontrollaktivitäten | G15: Verträge mit Agenturen, Influencern und Händlern regeln: Nutzung nur freigegebener Claims aus der Claim-Bibliothek, Freigabevorbehalt, Mitwirkung bei der Beseitigung, Haftung. Geprüft wird bei Vertragsschluss und Verlängerung. | H15: präventiv | I15: manuell | J15: bei Vertragsschluss und Verlängerung | K15: Einkauf mit Legal und Marketing | L15: Vertragsmuster; Vertragsliste mit Klauselstatus | M15: Stichprobe von 5 aktiven Verträgen: Klauseln enthalten. | N15: Anpassung (bestehende Vertragsmuster erweitern) | O15: Influencer-Briefing mit Claim-Bibliothek; Freigabe jedes Beitrags mit Umweltbezug | P15: Organisation | Q15: nein | R15: hoch | S15: ja | T15: RB C16; RB Kap. 6.10 (Baustein 7)
... A26: K22 | B26: 11 Überwachung des IKS | C26: Kontrollen wirken nicht oder werden umgangen, ohne dass es auffällt; Evidenz ist im Ernstfall nicht schnell verfügbar. | D26: alle; A12 | E26: KZ7 Nachvollziehbarkeit | F26: Überwachung | G26: Halbjährlicher 48-Stunden-Test (Dossiers zu drei zufällig gewählten Claims abrufen). Jährlicher Test von Ausgestaltung und Wirksamkeit der Schlüsselkontrollen. Bericht mit Kennzahlen an die Geschäftsleitung. | H26: detektiv | I26: manuell | J26: halbjährlich; jährlich | K26: Compliance bzw. Interne Revision; Geschäftsleitung (Review) | L26: Testprotokolle; Bericht an die Geschäftsleitung | M26: Durchsicht der Testprotokolle und des Berichts; Nachverfolgung festgestellter Mängel. | N26: Anpassung (bestehender Kontrolltestplan und Management-Review) | O26: Halbjahresbericht: Dossier-Vollständigkeit 96 %, zwei ablaufende Zertifikate, keine Abmahnung | P26: Organisation; 48-Stunden-Zielwert: Best Practice | Q26: ja | R26: mittel | S26: ja (halbjährlicher Review) | T26: RB C21, C22; RB Kap. 6.10 (Baustein 10)

Sheet Kontrollziele
A1: Kontrollziele KZ1–KZ9
A3: Nr. | B3: Kontrollziel | C3: Leitfrage | D3: EmpCo-Bezug | E3: Zugeordnete Kontrollen | F3: Anzahl
A4: KZ1 | B4: Vollständigkeit | C4: Sind alle Claims in allen Kanälen und bei allen Urhebern erfasst? | D4: A1–A14 | E4: K13, K18, K1, K16, K9, K8 | F4: =COUNTIF(Kontrollmatrix!$E$4:$E$26,"*KZ1*") -> 6
A5: KZ2 | B5: Zulässigkeit | C5: Berührt ein Claim ein Per-se-Verbot? | D5: A2–A5, A8, A10 | E5: K2, K18, K17, K5, K6, K21 | F5: =COUNTIF(Kontrollmatrix!$E$4:$E$26,"*KZ2*") -> 6
A6: KZ3 | B6: Tatsächlichkeit und Richtigkeit | C6: Ist der Claim vor Veröffentlichung belegt und die Methode begründet? | D6: A1, A12 | E6: K3, K15, K20, K11, K6, K21 | F6: =COUNTIF(Kontrollmatrix!$E$4:$E$26,"*KZ3*") -> 6
A7: KZ4 | B7: Darstellung | C7: Steht die Spezifizierung im selben Medium, ist Teil/Ganzes korrekt, fehlen keine wesentlichen Informationen? | D7: A2, A4, A9 | E7: K3, K20 | F7: =COUNTIF(Kontrollmatrix!$E$4:$E$26,"*KZ4*") -> 2
A8: KZ5 | B8: Gültigkeit | C8: Gelten Evidenz und Nutzungsrechte für den gesamten Nutzungszeitraum? | D8: A3, A12 | E8: K15, K7, K5 | F8: =COUNTIF(Kontrollmatrix!$E$4:$E$26,"*KZ5*") -> 3
A9: KZ6 | B9: Autorisierung | C9: Hat die zuständige Instanz freigegeben, ohne Selbstfreigabe? | D9: Organisation; A13 | E9: K4, K1, K14, K16 | F9: =COUNTIF(Kontrollmatrix!$E$4:$E$26,"*KZ6*") -> 4
A10: KZ7 | B10: Nachvollziehbarkeit | C10: Sind Audit Trail und Dossier vollständig und schnell abrufbar? | D10: A12 | E10: K12, K22 | F10: =COUNTIF(Kontrollmatrix!$E$4:$E$26,"*KZ7*") -> 2
A11: KZ8 | B11: Reaktionsfähigkeit | C11: Führen Trigger und Beanstandungen zeitnah zu Re-Validierung, Anpassung oder Rücknahme? | D11: A12–A14 | E11: K7, K19, K12 | F11: =COUNTIF(Kontrollmatrix!$E$4:$E$26,"*KZ8*") -> 3
A12: KZ9 | B12: Pflichtinformationen | C12: Sind die vorvertraglichen Pflichtinformationen in allen Verkaufskanälen vollständig und richtig? | D12: A11 | E12: K10 | F12: =COUNTIF(Kontrollmatrix!$E$4:$E$26,"*KZ9*") -> 1
A14: Quelle: Research-Basis Kap. 8.1 (KZ1–KZ8), ergänzt um KZ9; Arbeitsdokument Kap. 7.2. K23 (Rahmen) wirkt auf alle Kontrollziele und ist hier nicht einzeln gezählt.

Sheet Anforderungen
A1: EmpCo-Anforderungen A1–A14 und zugeordnete Kontrollen
A3: Nr. | B3: Anforderung | C3: EU | D3: Deutschland | E3: Verbindlichkeit | F3: Spezifisch zugeordnete Kontrollen
A4: A1 | B4: Irreführung über ökologische und soziale Merkmale sowie Zirkularität | C4: Art. 6 Abs. 1 lit. b UGP-RL | D4: § 5 Abs. 2 Nr. 1 UWG | E4: Pflicht (gilt über § 5 UWG auch B2B) | F4: K18, K3, K15, K7, K8, K11, K21
A5: A2 | B5: Keine allgemeine Umweltaussage ohne anerkannte hervorragende Umweltleistung oder Spezifizierung im selben Medium | C5: Anhang I Nr. 4a UGP-RL | D5: Anhang Nr. 4a UWG | E5: Pflicht (Per-se-Verbot) | F5: K2, K18, K17, K8, K19
A6: A3 | B6: Kein Nachhaltigkeitssiegel ohne Zertifizierungssystem oder staatliche Festsetzung | C6: Anhang I Nr. 2a UGP-RL | D6: Anhang Nr. 2a UWG | E6: Pflicht (Per-se-Verbot) | F6: K7, K8, K5, K19
A7: A4 | B7: Keine Aussage über das Ganze, wenn nur ein Aspekt betroffen ist | C7: Anhang I Nr. 4b UGP-RL | D7: Anhang Nr. 4b UWG | E7: Pflicht (Per-se-Verbot) | F7: K2, K3, K8, K19
A8: A5 | B8: Keine kompensationsbasierte Neutralitätsaussage für ein Produkt | C8: Anhang I Nr. 4c UGP-RL | D8: Anhang Nr. 4c UWG | E8: Pflicht (Per-se-Verbot) | F8: K2, K17, K8, K19
A9: A6 | B9: Zukunftsaussagen nur mit Umsetzungsplan und regelmäßiger Prüfung durch einen unabhängigen externen Sachverständigen | C9: Art. 6 Abs. 2 lit. d UGP-RL | D9: § 5 Abs. 3 Nr. 4 UWG (Nummer nach Sekundärquellen) | E9: Pflicht (bedingt: nur bei Nutzung) | F9: K11, K6
A10: A7 | B10: Keine Werbung mit irrelevanten Vorteilen | C10: Art. 6 Abs. 2 lit. e UGP-RL | D10: § 5 Abs. 3 Nr. 3 UWG | E10: Pflicht (Einzelfallprüfung) | F10: K2
A11: A8 | B11: Gesetzliche Anforderungen nicht als Besonderheit darstellen | C11: Anhang I Nr. 10a UGP-RL | D11: Anhang Nr. 10a UWG | E11: Pflicht (Per-se-Verbot) | F11: K2
A12: A9 | B12: Vergleiche: Methode, verglichene Produkte und Anbieter sowie Aktualisierung angeben | C12: Art. 7 Abs. 7 UGP-RL | D12: § 5b Abs. 3a UWG; § 6 UWG | E12: Pflicht | F12: K20
A13: A10 | B13: Keine Obsoleszenz-, Haltbarkeits-, Reparatur- und Update-Praktiken nach der Schwarzen Liste | C13: Anhang I Nr. 23d–23j UGP-RL | D13: Anhang Nr. 23d UWG | E13: Pflicht (Per-se-Verbote) | F13: K2, K17, K8, K21
A14: A11 | B14: Vorvertragliche Informationen: Gewährleistungshinweis, Garantie-Label, Updates, Reparatur und Ersatzteile, Lieferoptionen | C14: VRRL Art. 5, 6, 22a; DVO (EU) 2025/1960 | D14: Art. 246, 246a EGBGB | E14: Pflicht (teils abhängig von Herstellerdaten) | F14: K10
... A17: A14 | B17: Altbestände | C17: keine Übergangsregel; CPC Common Understanding | D17: § 15b UWG (beschlossen, noch nicht in Kraft) | E17: Durchsetzungsfrage; Stand nachhalten | F17: K19, K12
A19: Zusätzlich wirken auf alle Anforderungen die übergreifenden Kontrollen K23, K13, K4, K1, K14, K22. Quelle: Arbeitsdokument Kap. 2 (Anforderungskatalog).

Sheet Quellen
A1: Quellen und Validierungsstatus
A3: ID | B3: Quelle | C3: Fundstelle | D3: Status
A4: R1 | B4: Richtlinie (EU) 2024/825 („EmpCo“) | C4: https://eur-lex.europa.eu/eli/dir/2024/825/oj?locale=de | D4: Primärtext gesperrt; über Research-Basis und Sekundärquellen validiert
A5: R2 | B5: Richtlinie 2005/29/EG (UGP-RL), konsolidiert | C5: https://eur-lex.europa.eu/legal-content/DE/TXT/?uri=celex:32005L0029 | D5: wie R1
A6: R3 | B6: Richtlinie 2011/83/EU (VRRL), konsolidiert | C6: https://eur-lex.europa.eu/legal-content/DE/TXT/?uri=celex:32011L0083 | D6: wie R1
A7: R4 | B7: UWG n. F., BGBl. 2026 I Nr. 43 | C7: https://www.recht.bund.de/bgbl/1/2026/43/regelungstext.pdf?__blob=publicationFile&v=1 | D7: Paragrafen nach Sekundärquellen; vor Verwendung prüfen
A8: R5 | B8: Art. 246, 246a EGBGB (BGBl. 2026 I Nr. 28) | C8: https://shopbetreiber-blog.de/ab-27-9-2026-die-umsetzung-der-empco-rl-im-bgb-und-egbgb | D8: Sekundärquelle; Anknüpfung an Herstellerdaten und Lieferoptionen am 29.09.2026 per Websuche bestätigt
A9: R6 | B9: Durchführungsverordnung (EU) 2025/1960 (harmonisierter Hinweis und Label) | C9: https://eur-lex.europa.eu/eli/reg_impl/2025/1960/oj/eng | D9: über Research-Basis validiert
A10: R8 | B10: § 15b UWG, BT-Drs. 21/6215 und 21/8158 | C10: https://dserver.bundestag.de/btd/21/062/2106215.pdf | D10: beschlossen 24.09.2026, noch nicht in Kraft
A11: B1 | B11: Europäische Kommission: Q&A zur Richtlinie (EU) 2024/825 | C11: https://commission.europa.eu/document/download/3c257883-bb2a-4dd9-a6dc-501d587bb34f_en?filename=faq-empowerting-consumers-gtd.pdf | D11: nicht bindend
A12: B3 | B12: CPC-Netzwerk: Common Understanding zu Altbeständen (06/2026) | C12: https://commission.europa.eu/document/download/264d8c70-2f9a-4955-8e7b-154d55a9b684_en?filename=Final+CPC+common+understanding+on+old+stock+situations+June+2026.pdf | D12: nicht bindend; richtet sich an Behörden
A13: B4 | B13: IDW: Mustervermerke zur Prüfung von Umsetzungsplänen (22.09.2026) | C13: https://www.idw.de/news/idw-veroeffentlicht-mustervermerke-zur-pruefung-von-umsetzungsplaenen-fuer-kuenftige-umweltleistungen.html | D13: Veröffentlichung des Standardsetzers
A14: S3 | B14: IDW PS 982: Prüfung des IKS des internen und externen Berichtswesens | C14: https://www.bdo.de/de-de/services/audit-assurance/forensic-risk-compliance/internes-kontrollsystem-und-risikomanagement/prufung-von-internen-kontrollsystemen-nach-idw-ps-982 | D14: kostenpflichtig; Struktur nach BDO
... A17: I2 | B17: Arbeitsdokument „EmpCo in bestehenden GRC-Strukturen“ (29.09.2026); zitiert als „Word“ | C17: research/empco-uwg/EmpCo_GRC-Integration_CMS-RMS-IKS_2026-09-29.docx | D17: intern
A19: IDs wie im Arbeitsdokument (Anhang A). Normzitate vor externer Verwendung am Originaltext prüfen.
